<?xml version="1.0"?>
<robot xmlns:xacro="http://www.ros.org/wiki/xacro" >

    <xacro:include filename="inertial_macros.xacro"/>

    <material name="white">
        <color rgba="1 1 1 1" />
    </material>

    <material name="orange">
        <color rgba="1 0.3 0.1 1"/>
    </material>

    <material name="blue">
        <color rgba="0.2 0.2 1 1"/>
    </material>

    <material name="black">
        <color rgba="0 0 0 1"/>
    </material>

   <!-- BASE LINK -->

    <!-- BASE LINK -->
    <link name="base_link">
      <!-- You can add visual, collision, and inertial info here -->
    </link>

    <joint name="base_footprint_joint" type="fixed">
        <parent link="base_link"/>
        <child link="base_footprint"/>
        <origin xyz="0 0 0" rpy="0 0 0"/>
    </joint>

    <link name="base_footprint">
    </link>


    <!-- Fixed joint connecting base_link to chassis -->
    <joint name="base_to_chassis" type="fixed">
      <parent link="base_link"/>
      <child link="chassis"/>
      <origin xyz="0 0 0.2028" rpy="0 0 0"/>
    </joint>



   

    <link name="chassis">
        <visual>
            <origin xyz="2.2924 -0.00985747 0.0751" rpy="3.14159 0 1.5708"/>
            <geometry>
                  <mesh filename="file:///home/jay/ros2_ws/src/avone/description/assets/chassis.stl"/>
                 <!-- <mesh filename="package://avone/description/assets/chassis.stl"/> --> 
 
                 <!--  <box size="0.3 0.3 0.15"/> -->
            </geometry>
            <material name="blue"/>
        </visual>
        <collision>
            <origin xyz="2.2924 -0.00985747 0.0751" rpy="3.14159 0 1.5708"/>
            <geometry>
                    <mesh filename="file:///home/jay/ros2_ws/src/avone/description/assets/chassis.stl"/>      
                 <!--  <box size="0.3 0.3 0.15"/> -->
            </geometry>
        </collision>
        <xacro:inertial_box mass="152" x="2.4" y="0.67" z="0.5">
            <origin xyz="0.812063 -0.000266118 0.127823" rpy="0 0 0"/>
        </xacro:inertial_box>
   

     <!-- Part rear_suspension -->
    <visual>
      <origin xyz="-0.170629 -0.28192 0.105" rpy="3.14159 5.47382e-48 -0.0851102"/>
      <geometry>
        <mesh filename="file:///home/jay/ros2_ws/src/avone/description/assets/rear_suspension.stl"/>      
        
      </geometry>
      <material name="blue"/>
    </visual>
    <collision>
      <origin xyz="-0.170629 -0.28192 0.105" rpy="3.14159 5.47382e-48 -0.0851102"/>
      <geometry>
        <mesh filename="file:///home/jay/ros2_ws/src/avone/description/assets/rear_suspension.stl"/>      
      </geometry>
    </collision>

    <!-- Part rear_suspension_2 -->
    <visual>
      <origin xyz="0.189017 0.312761 0.105" rpy="-3.14159 2.33363e-61 -3.05648"/>
      <geometry>
        <mesh filename="file:///home/jay/ros2_ws/src/avone/description/assets/rear_suspension.stl"/>      
      </geometry>
      <material name="blue"/>
    </visual>
    <collision>
      <origin xyz="0.189017 0.312761 0.105" rpy="-3.14159 2.33363e-61 -3.05648"/>
      <geometry>
        <mesh filename="file:///home/jay/ros2_ws/src/avone/description/assets/rear_suspension.stl"/>      
      </geometry>
    </collision>

    <!-- Part front_suspension -->
    <visual>
      <origin xyz="1.6032 0.2935 0.075" rpy="3.14159 -1.54112e-16 1.5708"/>
      <geometry>
        <mesh filename="file:///home/jay/ros2_ws/src/avone/description/assets/front_suspension.stl"/>      
      </geometry>
      <material name="blue"/>
    </visual>
    <collision>
      <origin xyz="1.6032 0.2935 0.075" rpy="3.14159 -1.54112e-16 1.5708"/>
      <geometry>
        <mesh filename="file:///home/jay/ros2_ws/src/avone/description/assets/front_suspension.stl"/>      
      </geometry>
    </collision>

    <!-- Part front_suspension_2 -->
    <visual>
      <origin xyz="1.8748 -0.2935 0.075" rpy="-3.14159 1.54112e-16 -1.5708"/>
      <geometry>
        <mesh filename="file:///home/jay/ros2_ws/src/avone/description/assets/front_suspension.stl"/>      
      </geometry>
      <material name="blue"/>
    </visual>
    <collision>
      <origin xyz="1.8748 -0.2935 0.075" rpy="-3.14159 1.54112e-16 -1.5708"/>
      <geometry>
        <mesh filename="file:///home/jay/ros2_ws/src/avone/description/assets/front_suspension.stl"/>      
      </geometry>
    </collision>
  




  <!-- REAR WHEEL HUB LEFT -->

    <visual>
      <origin xyz="-0.181377 0.297001 -0.105" rpy="6.30462e-15 0 -6.18615e-05"/>
      <geometry>
        <mesh filename="file:///home/jay/ros2_ws/src/avone/description/assets/rear_wheel_hub.stl"/>      
      </geometry>
      <material name="white"/>
    </visual>
    <collision>
      <origin xyz="-0.181377 0.297001 -0.105" rpy="6.30462e-15 0 -6.18615e-05"/>
      <geometry>
        <mesh filename="file:///home/jay/ros2_ws/src/avone/description/assets/rear_wheel_hub.stl"/>      
      </geometry>
    </collision>
 

 

  <!-- REAR WHEEL HUB RIGHT -->

    <visual>
      <origin xyz="0.181423 -0.296978 -0.105" rpy="3.10966e-15 7.00787e-15 -3.14153"/>
      <geometry>
        <mesh filename="file:///home/jay/ros2_ws/src/avone/description/assets/rear_wheel_hub.stl"/>      
      </geometry>
      <material name="white"/>
    </visual>
    <collision>
      <origin xyz="0.181423 -0.296978 -0.105" rpy="3.10966e-15 7.00787e-15 -3.14153"/>
      <geometry>
        <mesh filename="file:///home/jay/ros2_ws/src/avone/description/assets/rear_wheel_hub.stl"/>      
      </geometry>
    </collision>
  </link>

  <gazebo reference="chassis">
    <material>Gazebo/Blue</material>
  </gazebo>



    <!-- LEFT WHEEL LINK (RLMotor) -->
    <joint name="RLMotor" type="continuous">
        <origin xyz="4.71381e-05 0.693977 3.30291e-15" rpy="1.5708 0 -6.18615e-05"/>
        <parent link="chassis"/>
        <child link="left_motor"/>
        <axis xyz="0 0 -1"/>

     <dynamics damping="0.2" friction="0.1"/>
      <limit effort="50" velocity="50"/>  <!-- up to 20 m/s -->    </joint>

    <link name="left_motor">
        <visual>
            <origin xyz="-8.09391e-17 7.65875e-18 0.17" rpy="1.5708 0 0"/>
            <geometry>
                    <mesh filename="file:///home/jay/ros2_ws/src/avone/description/assets/wheel.stl"/>      
                 <!--  <box size="0.3 0.3 0.15"/> -->

            </geometry>
            <material name="black"/>
        </visual>
        <collision>
            <origin xyz="-8.09391e-17 7.65875e-18 0.17" rpy="1.5708 0 0"/>
            <geometry>
                    <sphere radius="0.2"/> 
                 <!--  <box size="0.3 0.3 0.15"/> -->
            </geometry>
        </collision>
        <xacro:inertial_cylinder mass="9.8" length="0.2" radius="0.2">
            <origin xyz="-8.09407e-17 -1.33567e-17 0.0496398" rpy="0 0 0"/>
        </xacro:inertial_cylinder>
    </link>

    <gazebo reference="left_motor">
        <material>Gazebo/Grey</material>
    </gazebo>


    <!-- RIGHT WHEEL LINK (RRMotor) -->
    <joint name="RRMotor" type="continuous">
        <origin xyz="4.71381e-05 -0.693977 2.30371e-15" rpy="1.5708 0 -3.14153"/>
        <parent link="chassis"/>
        <child link="right_motor"/>
        <axis xyz="0 0 1"/>

      <dynamics damping="0.2" friction="0.1"/>
      <limit effort="50" velocity="50"/>  <!-- up to 20 m/s -->    </joint>

    <link name="right_motor">
        <visual>
            <origin xyz="-1.59877e-17 7.65404e-18 0.17" rpy="1.5708 0 0"/>
            <geometry>
                    <mesh filename="file:///home/jay/ros2_ws/src/avone/description/assets/wheel.stl"/>      
                 <!--  <box size="0.3 0.3 0.15"/> -->
            </geometry>
            <material name="black"/>
        </visual>
        <collision>
            <origin xyz="-1.59877e-17 7.65404e-18 0.17" rpy="1.5708 0 0"/>
            <geometry>
                     <sphere radius="0.2"/>    
                 <!--  <box size="0.3 0.3 0.15"/> -->
            </geometry>
        </collision>
        <xacro:inertial_cylinder mass="9.8" length="0.2" radius="0.2">
            <origin xyz="-1.66794e-17 -1.33614e-17 0.0496398" rpy="0 0 0"/>
        </xacro:inertial_cylinder>
    </link>

    <gazebo reference="right_motor">
        <material>Gazebo/Grey</material>
    </gazebo>


    <!-- FRONT RIGHT STEERING ASSEMBLY -->
    <!-- FRONT RIGHT STEERING ASSEMBLY -->
    <joint name="RSteer" type="revolute">
        <origin xyz="1.739 -0.584139 0.075" rpy="-3.14159 0 -1.5708"/>
        <parent link="chassis"/>
        <child link="front_right_wheel_hub"/>
        <axis xyz="0 0 -1"/>
        <limit effort="100" velocity="20" lower="-0.8" upper="0.8"/>
         
          <dynamics damping="0.1" friction="0.05"/>
    </joint>

    <link name="front_right_wheel_hub">
        <visual>
            <origin xyz="-0.290639 0.1358 0.18" rpy="-3.14159 0 0"/>
            <geometry>
                    <mesh filename="file:///home/jay/ros2_ws/src/avone/description/assets/front_wheel_hub.stl"/>      
                 <!--  <box size="0.3 0.3 0.15"/> -->
            </geometry>
            <material name="white"/>
        </visual>
        <collision>
            <origin xyz="-0.290639 0.1358 0.18" rpy="-3.14159 0 0"/>
            <geometry>
                    <mesh filename="file:///home/jay/ros2_ws/src/avone/description/assets/front_wheel_hub.stl"/>      
                 <!--  <box size="0.3 0.3 0.15"/> -->
            </geometry>
        </collision>
        <xacro:inertial_box mass="1.6" x="0.1" y="0.1" z="0.1">
            <origin xyz="0.0824722 0 0.09" rpy="0 0 0"/>
        </xacro:inertial_box>
    </link>

    <gazebo reference="front_right_wheel_hub">
        <material>Gazebo/Black</material>
    </gazebo>

   


    <joint name="FRWheel" type="continuous">
        <origin xyz="0.10836 0 0.09" rpy="1.5708 0 -1.5708"/>
        <parent link="front_right_wheel_hub"/>
        <child link="front_right_wheel"/>
        <axis xyz="0 0 1"/>
        <limit effort="50" velocity="100"/>
        <dynamics damping="0.0" friction="0.0"/>
    </joint>

    <link name="front_right_wheel">
        <visual>
            <origin xyz="2.22045e-16 0 0.17" rpy="1.5708 0 1.5708"/>
            <geometry>
                    <mesh filename="file:///home/jay/ros2_ws/src/avone/description/assets/wheel.stl"/>      
                 <!--  <box size="0.3 0.3 0.15"/> -->
            </geometry>
            <material name="black"/>
        </visual>
        <collision>
            <origin xyz="2.22045e-16 0 0.17" rpy="1.5708 0 1.5708"/>
            <geometry>
                   <!-- <mesh filename="file:///home/jay/ros2_ws/src/avone/description/assets/wheel.stl"/>      -->
                    <sphere radius="0.2"/>
                 <!--  <box size="0.3 0.3 0.15"/> -->
            </geometry>
        </collision>
        <xacro:inertial_cylinder mass="9.8" length="0.2" radius="0.2">
            <origin xyz="2.33038e-16 0 0.0496398" rpy="0 0 0"/>
        </xacro:inertial_cylinder>
    </link>

    <gazebo reference="front_right_wheel">
        <material>Gazebo/Grey</material>
    </gazebo>

 


    <!-- FRONT LEFT STEERING ASSEMBLY -->
    <joint name="LSteer" type="revolute">
        <origin xyz="1.739 0.584139 0.075" rpy="3.14159 0 1.5708"/>
        <parent link="chassis"/>
        <child link="front_left_wheel_hub"/>
        <axis xyz="0 0 -1"/>
         <limit effort="100" velocity="20" lower="-0.8" upper="0.8"/>
         
          <dynamics damping="0.1" friction="0.05"/>
    </joint>

    <link name="front_left_wheel_hub">
        <visual>
        <origin xyz="-0.290639 0.1358 0.18" rpy="3.14159 0 0"/>
        <geometry>
                    <mesh filename="file:///home/jay/ros2_ws/src/avone/description/assets/front_wheel_hub.stl"/>      
                 <!--  <box size="0.3 0.3 0.15"/> -->
        </geometry>
        <material name="white"/>
        </visual>
        <collision>
        <origin xyz="-0.290639 0.1358 0.18" rpy="3.14159 0 0"/>
        <geometry>
                    <mesh filename="file:///home/jay/ros2_ws/src/avone/description/assets/front_wheel_hub.stl"/>      
                 <!--  <box size="0.3 0.3 0.15"/> -->
        </geometry>
        </collision>
        <xacro:inertial_box mass="1.6" x="0.1" y="0.1" z="0.1">
        <origin xyz="0.0824722 0 0.09" rpy="0 0 0"/>
        </xacro:inertial_box>
    </link>

    <gazebo reference="front_left_wheel_hub">
        <material>Gazebo/Black</material>
    </gazebo>



    <joint name="FLWheel" type="continuous">
        <origin xyz="0.10836 0 0.09" rpy="1.5708 0 -1.5708"/>
        <parent link="front_left_wheel_hub"/>
        <child link="front_left_wheel"/>
        <axis xyz="0 0 1"/>
        <limit effort="50" velocity="100"/>
        <dynamics damping="0.0" friction="0.0"/>
    </joint>

 

    <link name="front_left_wheel">
        <visual>
        <origin xyz="0 0 0.17" rpy="1.5708 0 0"/>
        <geometry>
                    <mesh filename="file:///home/jay/ros2_ws/src/avone/description/assets/wheel.stl"/>      
                 <!--  <box size="0.3 0.3 0.15"/> -->
        </geometry>
        <material name="black"/>
        </visual>
        <collision>
        <origin xyz="0 0 0.17" rpy="1.5708 0 0"/>
        <geometry>
                     <sphere radius="0.2"/> 
                 <!--  <box size="0.3 0.3 0.15"/> -->
        </geometry>
        </collision>
        <xacro:inertial_cylinder mass="9.8" length="0.2" radius="0.2">
        <origin xyz="0 0 0.0496398" rpy="0 0 0"/>
        </xacro:inertial_cylinder>
    </link>

    <gazebo reference="front_left_wheel">
        <material>Gazebo/Grey</material>
    </gazebo>

<!--

        <gazebo>

           <plugin
                filename="libignition-gazebo-ackermann-steering-system.so"
                name="ignition::gazebo::systems::AckermannSteering">
                <left_joint>RLMotor</left_joint>
                <right_joint>RRMotor</right_joint>
                <left_steering_joint>LSteer</left_steering_joint>
                <right_steering_joint>RSteer</right_steering_joint>
                <wheel_separation>1.05</wheel_separation>
                <kingpin_width>1.17</kingpin_width>
                <wheel_base>1.74</wheel_base>
                <steering_limit>0.8</steering_limit>
                <wheel_radius>0.203</wheel_radius>
                <odom_publish_frequency>50</odom_publish_frequency>
                <max_velocity>10</max_velocity>
                <max_acceleration>5.0</max_acceleration>
             
               
                 <odom_topic>/model/my_robot/odometry</odom_topic>
              <tf_topic>/model/my_robot/tf</tf_topic>
              <frame_id>odom</frame_id>
              <child_frame_id>base_link</child_frame_id>
                
              
            </plugin>



        

           <plugin name="ignition::gazebo::systems::PosePublisher"
        filename="libignition-gazebo-pose-publisher-system.so">
          <publish_link_pose>true</publish_link_pose>
          <use_pose_vector_msg>true</use_pose_vector_msg>
          <static_publisher>true</static_publisher>
          <static_update_frequency>50</static_update_frequency>
        </plugin>


 

     
              
              

       


   

      <plugin filename="libignition-gazebo-joint-state-publisher-system.so"
        name="ignition::gazebo::systems::JointStatePublisher">
          <topic>joint_states</topic>
          <update_rate>50</update_rate>
      </plugin>
       
   

      </gazebo>
 

-->



</robot>